<?xml version="1.0"?>
<!-- Basic URDF components for PhantomX Pincher Arm
BSD 3-Clause License

Copyright (c) 2021, Willow Garage, Inc.
All rights reserved.

Redistribution and use in source and binary forms, with or without
modification, are permitted provided that the following conditions are met:

    * Redistributions of source code must retain the above copyright
      notice, this list of conditions and the following disclaimer.
    * Redistributions in binary form must reproduce the above copyright
      notice, this list of conditions and the following disclaimer in the
      documentation and/or other materials provided with the distribution.
    * Neither the name of the Willow Garage, Inc. nor the names of its
      contributors may be used to endorse or promote products derived from
      this software without specific prior written permission.

THIS SOFTWARE IS PROVIDED BY THE COPYRIGHT HOLDERS AND CONTRIBUTORS "AS IS"
AND ANY EXPRESS OR IMPLIED WARRANTIES, INCLUDING, BUT NOT LIMITED TO, THE
IMPLIED WARRANTIES OF MERCHANTABILITY AND FITNESS FOR A PARTICULAR PURPOSE
ARE DISCLAIMED. IN NO EVENT SHALL THE COPYRIGHT OWNER OR CONTRIBUTORS BE
LIABLE FOR ANY DIRECT, INDIRECT, INCIDENTAL, SPECIAL, EXEMPLARY, OR
CONSEQUENTIAL DAMAGES (INCLUDING, BUT NOT LIMITED TO, PROCUREMENT OF
SUBSTITUTE GOODS OR SERVICES; LOSS OF USE, DATA, OR PROFITS; OR BUSINESS
INTERRUPTION) HOWEVER CAUSED AND ON ANY THEORY OF LIABILITY, WHETHER IN
CONTRACT, STRICT LIABILITY, OR TORT (INCLUDING NEGLIGENCE OR OTHERWISE)
ARISING IN ANY WAY OUT OF THE USE OF THIS SOFTWARE, EVEN IF ADVISED OF THE
POSSIBILITY OF SUCH DAMAGE.
-->

<robot xmlns:xacro="http://ros.org/wiki/xacro">

  <xacro:property name="M_SCALE" value="0.001"/>
  <xacro:property name="F2_HEIGHT" value="0.0265"/>
  <xacro:property name="F3_HEIGHT" value="0.009"/>
  <xacro:property name="F4_HEIGHT" value="0.0525"/>
  <xacro:property name="F10_HEIGHT" value="0.004"/>
  <xacro:property name="AX12_HEIGHT" value="0.0385"/>
  <xacro:property name="AX12_WIDTH" value="0.038"/>
  <xacro:property name="AX12_LENGTH" value="0.050"/>
  <xacro:property name="AX12_RANGE" value="5.236"/>  <!-- 300 degrees -->

  <!-- Calculates the inertial properties of a bounding box. From
       https://en.wikipedia.org/wiki/List_of_moments_of_inertia#List_of_3D_inertia_tensors-->
  <xacro:macro name="box_inertia" params="length width height mass x=0 y=0 z=0">
    <inertial>
      <mass value="${mass}"/>
      <origin xyz="${x} ${y} ${z}"/>
      <inertia ixx="${mass/12*(width**2+height**2)}" ixy="0" ixz="0"
               iyy="${mass/12*(length**2+height**2)}" iyz="0"
               izz="${mass/12*(width**2+length**2)}"/>


    </inertial>
  </xacro:macro>
  <xacro:macro name="arm_mount" params="parent name color *origin">
    <joint name="${name}_joint" type="fixed">
      <xacro:insert_block name="origin"/>
      <parent link="${parent}"/>
      <child link="${name}_link"/>
    </joint>

    <link name="${name}_link">
      <xacro:box_inertia length="0.074" width="0.074" height="0.004" mass="0.018"/>

      <visual>
        <origin xyz="-0.028 -0.0493 0.014" rpy="0.0 0.0 -${pi/2}"/>
        <geometry>
          <mesh filename="package://pincher_arm_description/meshes/mount.stl" scale="${M_SCALE} ${M_SCALE} ${M_SCALE}"/>
        </geometry>
        <material name="${color}"/>
      </visual>

      <collision>
        <origin xyz="-0.01 0.0 0.0165" rpy="0.0 0.0 0.0"/>
        <geometry>
          <box size="0.074 0.074 0.004"/>
        </geometry>
      </collision>
    </link>
    
    <gazebo reference="${name}_link">
      <material>Gazebo/${color}</material>
      <selfCollide>true</selfCollide>
      <gravity>true</gravity>
    </gazebo>
  </xacro:macro>

  <xacro:macro name="dynamixel_AX12_fixed" params="parent name *origin">
    <joint name="${name}_joint" type="fixed">
      <xacro:insert_block name="origin"/>
      <parent link="${parent}"/>
      <child link="${name}_link"/>
    </joint>

    <link name="${name}_link">
      <xacro:box_inertia length="${AX12_HEIGHT}" width="${AX12_WIDTH}" height="${AX12_LENGTH}" mass="0.055" z="-0.01241"/>

      <visual>
        <origin xyz="0 0 0" rpy="0 0 0"/>
        <geometry>
          <mesh filename="package://pincher_arm_description/meshes/ax12_box.stl" scale="${M_SCALE} ${M_SCALE} ${M_SCALE}"/>
        </geometry>
        <material name="Black"/>
      </visual>

      <collision>
        <origin xyz="0.0 0.0 -0.01241" rpy="0 0 0"/>
        <geometry>
          <box size="${AX12_HEIGHT} ${AX12_WIDTH} ${AX12_LENGTH}"/>
        </geometry>
      </collision>
    </link>
    <gazebo reference="${name}_link">
      <material>Gazebo/Black</material>
      <selfCollide>true</selfCollide>
      <gravity>true</gravity>
    </gazebo>
  </xacro:macro>

  <xacro:macro name="bioloid_F10_fixed" params="parent name color *origin">
    <joint name="${name}_joint" type="fixed">
      <xacro:insert_block name="origin"/>
      <parent link="${parent}"/>
      <child link="${name}_link"/>
    </joint>

    <link name="${name}_link">
      <xacro:box_inertia length="0.025" width="0.038" height="0.004" mass="0.004"/>

      <visual>
        <origin xyz="0 0 0" rpy="0 0 0"/>
        <geometry>
          <mesh filename="package://pincher_arm_description/meshes/F10.stl" scale="${M_SCALE} ${M_SCALE} ${M_SCALE}"/>
        </geometry>
        <material name="${color}"/>
      </visual>

      <collision>
        <origin xyz="0.0 0.0 0.0" rpy="0 0 0"/>
        <geometry>
          <box size="0.025 0.038 0.004"/>
        </geometry>
      </collision>
    </link>
    
    <gazebo reference="${name}_link">
      <material>Gazebo/${color}</material>
      <selfCollide>true</selfCollide>
      <gravity>true</gravity>
    </gazebo>
  </xacro:macro>

  <xacro:macro name="bioloid_F3_fixed" params="parent name color *origin">
    <joint name="${name}_joint" type="fixed">
      <xacro:insert_block name="origin"/>
      <parent link="${parent}"/>
      <child link="${name}_link"/>
    </joint>

    <link name="${name}_link">
      <xacro:box_inertia length="0.025" width="0.038" height="0.009" mass="0.005"/>

      <visual>
        <origin xyz="0 0 0" rpy="0 0 0"/>
        <geometry>
          <mesh filename="package://pincher_arm_description/meshes/F3.stl" scale="${M_SCALE} ${M_SCALE} ${M_SCALE}"/>
        </geometry>
        <material name="${color}"/>
      </visual>

      <collision>
        <origin xyz="0.0 0.0 -0.0045" rpy="0 0 0"/>
        <geometry>
          <box size="0.025 0.038 0.009"/>
        </geometry>
      </collision>
    </link>
    
    <gazebo reference="${name}_link">
      <material>Gazebo/${color}</material>
      <selfCollide>true</selfCollide>
      <gravity>true</gravity>
    </gazebo>
  </xacro:macro>

  <xacro:macro name="bioloid_F3_revolute" params="parent name color llimit ulimit vlimit *origin">
    <joint name="${name}_joint" type="revolute">
      <xacro:insert_block name="origin"/>
      <axis xyz="0 0 -1"/>
      <limit effort="30" velocity="${vlimit}" lower="${llimit}" upper="${ulimit}"/>
      <dynamics friction="0.13"/>
      <parent link="${parent}"/>
      <child link="${name}_link"/>
    </joint>

    <link name="${name}_link">
      <xacro:box_inertia length="0.025" width="0.038" height="0.009" mass="0.008"/>

      <visual>
        <origin xyz="0 0 0" rpy="0 0 0"/>
        <geometry>
          <mesh filename="package://pincher_arm_description/meshes/F3.stl" scale="${M_SCALE} ${M_SCALE} ${M_SCALE}"/>
        </geometry>
        <material name="${color}"/>
      </visual>

      <collision>
        <origin xyz="0.0 0.0 -0.0045" rpy="0 0 0"/>
        <geometry>
          <box size="0.025 0.038 0.009"/>
        </geometry>
      </collision>
    </link>

    <gazebo reference="${name}_link">
      <material>Gazebo/${color}</material>
      <selfCollide>true</selfCollide>
      <gravity>true</gravity>
    </gazebo>
  </xacro:macro>

  <xacro:macro name="bioloid_F2_revolute" params="parent name color llimit ulimit vlimit *origin">
    <joint name="${name}_joint" type="revolute">
      <xacro:insert_block name="origin"/>
      <axis xyz="0 1 0"/>
      <limit effort="30" velocity="${vlimit}" lower="${llimit}" upper="${ulimit}"/>
      <dynamics friction="0.13"/>
      <parent link="${parent}"/>
      <child link="${name}_link"/>
    </joint>

    <link name="${name}_link">
      <xacro:box_inertia length="0.025" width="0.0485" height="0.0375" mass="0.010"/>

      <visual>
        <origin xyz="0 0 0" rpy="0 0 0"/>
        <geometry>
          <mesh filename="package://pincher_arm_description/meshes/F2.stl" scale="${M_SCALE} ${M_SCALE} ${M_SCALE}"/>
        </geometry>
        <material name="${color}"/>
      </visual>

      <collision>
        <origin xyz="0.0 0.0 0.00775" rpy="0 0 0"/>
        <geometry>
          <box size="0.025 0.0485 0.0375"/>
        </geometry>
      </collision>
    </link>
    
    <gazebo reference="${name}_link">
      <material>Gazebo/${color}</material>
      <selfCollide>true</selfCollide>
      <gravity>true</gravity>
    </gazebo>
  </xacro:macro>

  <xacro:macro name="bioloid_F4_revolute" params="parent name color llimit ulimit vlimit *origin">
    <joint name="${name}_joint" type="revolute">
      <xacro:insert_block name="origin"/>
      <axis xyz="0 1 0"/>
      <limit effort="30" velocity="${vlimit}" lower="${llimit}" upper="${ulimit}"/>
      <dynamics friction="0.13"/>
      <parent link="${parent}"/>
      <child link="${name}_link"/>
    </joint>

    <link name="${name}_link">
      <xacro:box_inertia length="0.028" width="0.0485" height="0.065" mass="0.016"/>

      <visual>
        <origin xyz="0 0 0" rpy="0 0 0"/>
        <geometry>
          <mesh filename="package://pincher_arm_description/meshes/F4.stl" scale="${M_SCALE} ${M_SCALE} ${M_SCALE}"/>
        </geometry>
        <material name="${color}"/>
      </visual>

      <collision>
        <origin xyz="0.0 0.0 0.0215" rpy="0 0 0"/>
        <geometry>
          <box size="0.028 0.0485 0.065"/>
        </geometry>
      </collision>
    </link>
    
    <gazebo reference="${name}_link">
      <material>Gazebo/${color}</material>
      <selfCollide>true</selfCollide>
      <gravity>true</gravity>
    </gazebo>
  </xacro:macro>
  
  <xacro:macro name="gripper_finger_base" params="parent name color *origin">
    <joint name="${name}_joint" type="fixed">
      <xacro:insert_block name="origin"/>
      <parent link="${parent}"/>
      <child link="${name}_link"/>
    </joint>
    
    <link name="${name}_link">
      <xacro:box_inertia length="0.002" width="0.075" height="0.040" mass="0.00001"/>
      <visual>
        <origin xyz="0 0 0" rpy="0 0 0"/>
        <geometry>
          <box size="0.002 0.075 0.040"/>
        </geometry>
        <material name="${color}"/>
      </visual>
      
      <collision>
        <geometry>
          <box size="0.002 0.075 0.040"/>
        </geometry>
      </collision>
    </link >
    
    <gazebo reference="${name}_link">
      <material>Gazebo/${color}</material>
      <selfCollide>true</selfCollide>
      <gravity>true</gravity>
    </gazebo>
  </xacro:macro>
  
  <xacro:macro name="pincher_finger" params="name color *origin">
    <link name="${name}_link">
      <xacro:box_inertia length="0.036" width="0.028" height="0.004" mass="0.00001"/>
      <visual>
        <xacro:insert_block name="origin"/>
        <geometry>
          <mesh filename="package://pincher_arm_description/meshes/pincher_finger.stl" scale=".01 .01 .01"/>
        </geometry>
        <material name="${color}"/>
      </visual>
      <collision>
        <xacro:insert_block name="origin"/>
        <geometry>
          <box size="0.023 0.028 0.038"/>
        </geometry>
      </collision>
    </link>
  
    <gazebo reference="${name}_link">
      <material>Gazebo/${color}</material>
      <selfCollide>true</selfCollide>
      <gravity>true</gravity>
    </gazebo>
  </xacro:macro>
</robot>
